<?xml version="1.0" ?>
<robot name="my_robot" xmlns:xarco="http://www.ros.org/wiki/xarco">

	<!-- TODO include and var xarco error -->
	<!-- <xarco:include filename="$(find world_setup)/urdf/robot.gazebo"/> -->

	<!-- <xacro:property name="camera_size" value="0.05" />  -->
	<!-- ${camera_size} -->

	<link name="link_chassis">
		<pose>0 0 0.1 0 0 0</pose>
		<inertial>
			<origin rpy="0 0 0" xyz="0 0 0.1"/>
			<mass value="1"/>
			<inertia ixx="1.0" ixy="0.0" ixz="0.0" iyy="1.0" iyz="0.0" izz="1.0"/>
		</inertial>
		<collision name="collision_chassis">
			<geometry>
				<box size="1 1 2"/>
			</geometry>
		</collision>
		<visual name="visual">
			<origin rpy="0 0 0" xyz="0 0 0"/>
			<geometry>
				<box size="1 1 2"/>
			</geometry>
		</visual>
	</link>

	<joint name="joint_1" type="continuous">
		<origin rpy="0 0 0" xyz="0.6 0 0.8"/>
		<parent link="link_chassis"/>
		<child link="link_arm"/>
	</joint>

	<link name="link_arm">
		<pose>0 0 0 0 0 0</pose>
		<inertial>
			<origin rpy="0 0 0" xyz="0 0 0"/>
			<mass value="0.5"/>
			<inertia ixx="1.0" ixy="0.0" ixz="0.0" iyy="1.0" iyz="0.0" izz="1.0"/>
		</inertial>
		<collision name="collision_chassis">
			<geometry>
				<box size="0.2 0.2 1"/>
			</geometry>
		</collision>
		<visual name="visual">
			<origin rpy="0 0 0" xyz="0 0 0"/>
			<geometry>
				<box size="0.2 0.2 1"/>
			</geometry>
		</visual>
	</link>

	<joint name="camera_joint" type="fixed">
		<axis xyz="0 1 0"/>
		<origin rpy="0 0 0" xyz="1 0 1"/>
		<parent link="link_arm"/>
		<child link="camera_link"/>
	</joint>

	<!-- Camera -->
	<link name="camera_link">
		<collision>
			<origin rpy="0 0 0" xyz="0 0 0"/>
			<geometry>
				<box size="0.1 0.1 0.1"/>
			</geometry>
		</collision>
		<visual>
			<origin rpy="0 0 0" xyz="0 0 0"/>
			<geometry>
				<box size="0.1 0.1 0.1"/>
			</geometry>
			<material name="red"/>
		</visual>
		<inertial>
			<mass value="0.1"/>
			<origin rpy="0 0 0" xyz="0 0 0"/>
			<inertia ixx="0.1" ixy="0" ixz="0" iyy="0.1" iyz="0" izz="0.1"/>
		</inertial>
	</link>

	<gazebo reference="camera_link">
		<sensor name="camera1" type="camera">
			<update_rate>30.0</update_rate>
			<camera name="head">
				<horizontal_fov>1.3962634</horizontal_fov>
				<image>
					<width>400</width>
					<height>400</height>
					<format>R8G8B8</format>
				</image>
				<clip>
					<near>0.02</near>
					<far>300</far>
				</clip>
				<noise>
					<type>gaussian</type>
					<mean>0.0</mean>
					<stddev>0.007</stddev>
				</noise>
			</camera>
			<plugin filename="libgazebo_ros_camera.so" name="camera_controller">
				<alwaysOn>true</alwaysOn>
				<updateRate>0.0</updateRate>
				<cameraName>my_robot/camera1</cameraName>
				<imageTopicName>image_raw</imageTopicName>
				<cameraInfoTopicName>camera_info</cameraInfoTopicName>
				<frameName>camera_link</frameName>
				<hackBaseline>0.07</hackBaseline>
				<distortionK1>0.0</distortionK1>
				<distortionK2>0.0</distortionK2>
				<distortionK3>0.0</distortionK3>
				<distortionT1>0.0</distortionT1>
				<distortionT2>0.0</distortionT2>
			</plugin>
		</sensor>
	</gazebo>

</robot>
