<?xml version="1.0" ?>
<robot name="my_robot" xmlns:xacro="http://www.ros.org/wiki/xacro">

    <xacro:property name="camera_size" value="0.1 0.1 0.1"/>
    <xacro:property name="link_chassis_size" value="2 1 0.5"/>
    <xacro:property name="link_arm_size" value="0.2 0.2 1"/>
    <xacro:property name="wheel_length" value="0.2"/>
    <xacro:property name="wheel_radius" value="0.5"/>
    <xacro:property name="wheel_rpy" value="0 1.6 1.6"/>

	<xacro:include filename="$(find world_setup)/urdf/robot.gazebo"/>


	<material name="blue">
		<color rgba="0.203 0.238 0.285 1.0"/>
	</material>

<!-- 	<gazebo reference="link_chassis">
    	<material>Gazebo/Blue</material>
	</gazebo> -->

	<gazebo>
		<plugin filename="libgazebo_ros_diff_drive.so" name="differential_drive_controller">
			<legacyMode>false</legacyMode>
			<alwaysOn>true</alwaysOn>
			<updateRate>20</updateRate>
			<leftJoint>joint_left_wheel</leftJoint>
			<rightJoint>joint_right_wheel</rightJoint>
			<wheelSeparation>1</wheelSeparation> <!-- box_y => origin_y*2 -->
			<wheelDiameter>${wheel_radius}*2</wheelDiameter>
			<torque>0.1</torque>
			<commandTopic>cmd_vel</commandTopic>
			<odometryTopic>odom</odometryTopic>
			<odometryFrame>odom</odometryFrame>
			<robotBaseFrame>link_chassis</robotBaseFrame>
		</plugin>
	</gazebo>



	<link name="link_chassis">
		<pose>0 0 0.1 0 0 0</pose>
		<inertial>
			<origin rpy="0 0 0" xyz="0 0 0.1"/>
			<mass value="1"/>
			<inertia ixx="1.0" ixy="0.0" ixz="0.0" iyy="1.0" iyz="0.0" izz="1.0"/>
		</inertial>
		<collision name="collision_chassis">
			<geometry>
				<box size="${link_chassis_size}"/>
			</geometry>
		</collision>
		<visual name="visual">
			<origin rpy="0 0 0" xyz="0 0 0"/>
			<geometry>
				<box size="${link_chassis_size}"/>
			</geometry>
			<material name="blue"/>
		</visual>
	</link>



	<joint name="joint_right_wheel" type="continuous">
		<origin rpy="0 0 0" xyz="-0.8 0.5 0"/>
		<parent link="link_chassis"/>
		<child link="link_right_wheel"/>
		<axis rpy="0 0 0" xyz="0 1 0"/>
		<limit effort="10000" velocity="1000"/>
		<joint_properties damping="1.0" friction="1.0"/>
	</joint>

	<link name="link_right_wheel">
		<inertial>
			<origin rpy="${wheel_rpy}" xyz="0 0 0"/>
			<mass value="0.2"/>
			<inertia ixx="0.005" ixy="0.0" ixz="0.0" iyy="0.005" iyz="0.0" izz="0.01"/>
		</inertial>
		<collision name="collision_right_wheel">
			<origin rpy="${wheel_rpy}" xyz="0 0 0"/>
			<geometry>
				<cylinder length="${wheel_length}" radius="${wheel_radius}"/>
			</geometry>
		</collision>
		<visual name="visual">
			<origin rpy="${wheel_rpy}" xyz="0 0 0"/>
			<geometry>
				<cylinder length="${wheel_length}" radius="${wheel_radius}"/>
			</geometry>

		</visual>
	</link>


	<joint name="joint_left_wheel" type="continuous">
		<origin rpy="0 0 0" xyz="-0.8 -0.5 0"/>
		<parent link="link_chassis"/>
		<child link="link_left_wheel"/>
		<axis rpy="0 0 0" xyz="0 1 0"/>
		<limit effort="10000" velocity="1000"/>
		<joint_properties damping="1.0" friction="1.0"/>
	</joint>

	<link name="link_left_wheel">
		<inertial>
			<origin rpy="${wheel_rpy}" xyz="0 0 0"/>
			<mass value="0.2"/>
			<inertia ixx="0.005" ixy="0.0" ixz="0.0" iyy="0.005" iyz="0.0" izz="0.01"/>
		</inertial>
		<collision name="collision_right_wheel">
			<origin rpy="${wheel_rpy}" xyz="0 0 0"/>
			<geometry>
				<cylinder length="${wheel_length}" radius="${wheel_radius}"/>
			</geometry>
		</collision>
		<visual name="visual">
			<origin rpy="${wheel_rpy}" xyz="0 0 0"/>
			<geometry>
				<cylinder length="${wheel_length}" radius="${wheel_radius}"/>
			</geometry>

		</visual>
	</link>


	<joint name="joint_right_wheel_f" type="continuous">
		<origin rpy="0 0 0" xyz="0.8 0.5 0"/>
		<parent link="link_chassis"/>
		<child link="link_right_wheel_f"/>
		<axis rpy="0 0 0" xyz="0 1 0"/>
		<limit effort="10000" velocity="1000"/>
		<joint_properties damping="1.0" friction="1.0"/>
	</joint>

	<link name="link_right_wheel_f">
		<inertial>
			<origin rpy="${wheel_rpy}" xyz="0 0 0"/>
			<mass value="0.2"/>
			<inertia ixx="0.005" ixy="0.0" ixz="0.0" iyy="0.005" iyz="0.0" izz="0.01"/>
		</inertial>
		<collision name="collision_right_wheel">
			<origin rpy="${wheel_rpy}" xyz="0 0 0"/>
			<geometry>
				<cylinder length="${wheel_length}" radius="${wheel_radius}"/>
			</geometry>
		</collision>
		<visual name="visual">
			<origin rpy="${wheel_rpy}" xyz="0 0 0"/>
			<geometry>
				<cylinder length="${wheel_length}" radius="${wheel_radius}"/>
			</geometry>

		</visual>
	</link>


	<joint name="joint_left_wheel_f" type="continuous">
		<origin rpy="0 0 0" xyz="0.8 -0.5 0"/>
		<parent link="link_chassis"/>
		<child link="link_left_wheel_f"/>
		<axis rpy="0 0 0" xyz="0 1 0"/>
		<limit effort="10000" velocity="1000"/>
		<joint_properties damping="1.0" friction="1.0"/>
	</joint>

	<link name="link_left_wheel_f">
		<inertial>
			<origin rpy="${wheel_rpy}" xyz="0 0 0"/>
			<mass value="0.2"/>
			<inertia ixx="0.005" ixy="0.0" ixz="0.0" iyy="0.005" iyz="0.0" izz="0.01"/>
		</inertial>
		<collision name="collision_right_wheel">
			<origin rpy="${wheel_rpy}" xyz="0 0 0"/>
			<geometry>
				<cylinder length="${wheel_length}" radius="${wheel_radius}"/>
			</geometry>
		</collision>
		<visual name="visual">
			<origin rpy="${wheel_rpy}" xyz="0 0 0"/>
			<geometry>
				<cylinder length="${wheel_length}" radius="${wheel_radius}"/>
			</geometry>

		</visual>
	</link>



	<joint name="joint_1" type="fixed">
		<origin rpy="0 0 0" xyz="0.6 0 0.5"/>
		<parent link="link_chassis"/>
		<child link="link_arm"/>
	</joint>

	<link name="link_arm">
		<pose>0 0 0 0 0 0</pose>
		<inertial>
			<origin rpy="0 0 0" xyz="0 0 0"/>
			<mass value="0.5"/>
			<inertia ixx="1.0" ixy="0.0" ixz="0.0" iyy="1.0" iyz="0.0" izz="1.0"/>
		</inertial>
		<collision name="collision_chassis">
			<geometry>
				<box size="${link_arm_size}"/>
			</geometry>
		</collision>
		<visual name="visual">
			<origin rpy="0 0 0" xyz="0 0 0"/>
			<geometry>
				<box size="${link_arm_size}"/>
			</geometry>
		</visual>
	</link>

	<joint name="camera_joint" type="fixed">
		<axis xyz="0 1 0"/>
		<origin rpy="0 0 0" xyz="0.2 0 0.5"/>
		<parent link="link_arm"/>
		<child link="camera_link"/>
	</joint>

	<!-- Camera -->
	<link name="camera_link">
		<collision>
			<origin rpy="0 0 0" xyz="0 0 0"/>
			<geometry>
				<box size="${camera_size}"/>
			</geometry>
		</collision>
		<visual>
			<origin rpy="0 0 0" xyz="0 0 0"/>
			<geometry>
				<box size="${camera_size}"/>
			</geometry>
		</visual>
		<inertial>
			<mass value="0.1"/>
			<origin rpy="0 0 0" xyz="0 0 0"/>
			<inertia ixx="0.1" ixy="0" ixz="0" iyy="0.1" iyz="0" izz="0.1"/>
		</inertial>
	</link>

</robot>
